package FinalConceptPackage;

public class FinallyConcept {

	public static void main(String[] args) {
		test2();
	}
	
	public static void test1() {
		try {
			System.out.println("inside test1 method");
			throw new RuntimeException("test");
		}catch(Exception E) {
			System.out.println("inside catch block");
		}
		
		finally {	//whatever the exception is coming it doesn't matter. Finally block will be run always
			System.out.println("inside finally block");
		}
	}
	
	public static void test2() {
		try {
		System.out.println("inside test2");
		}
		finally {
			System.out.println("finally test2");
		}
	}

}
